[2025-04-09T16:20:30.508+0000] {taskinstance.py:1157} INFO - Dependencies all met for dep_context=non-requeueable deps ti=<TaskInstance: ecommerce_pipeline.generate_data scheduled__2023-01-01T11:00:00+00:00 [queued]>
[2025-04-09T16:20:30.563+0000] {taskinstance.py:1157} INFO - Dependencies all met for dep_context=requeueable deps ti=<TaskInstance: ecommerce_pipeline.generate_data scheduled__2023-01-01T11:00:00+00:00 [queued]>
[2025-04-09T16:20:30.568+0000] {taskinstance.py:1359} INFO - Starting attempt 1 of 2
[2025-04-09T16:20:30.661+0000] {taskinstance.py:1380} INFO - Executing <Task(PythonOperator): generate_data> on 2023-01-01 11:00:00+00:00
[2025-04-09T16:20:30.680+0000] {standard_task_runner.py:57} INFO - Started process 192 to run task
[2025-04-09T16:20:30.753+0000] {standard_task_runner.py:84} INFO - Running: ['***', 'tasks', 'run', 'ecommerce_pipeline', 'generate_data', 'scheduled__2023-01-01T11:00:00+00:00', '--job-id', '42', '--raw', '--subdir', 'DAGS_FOLDER/dags_1.py', '--cfg-path', '/tmp/tmp89t_gmfc']
[2025-04-09T16:20:30.759+0000] {standard_task_runner.py:85} INFO - Job 42: Subtask generate_data
[2025-04-09T16:20:31.030+0000] {task_command.py:415} INFO - Running <TaskInstance: ecommerce_pipeline.generate_data scheduled__2023-01-01T11:00:00+00:00 [running]> on host db3312bb44e3
[2025-04-09T16:20:31.425+0000] {taskinstance.py:1660} INFO - Exporting env vars: AIRFLOW_CTX_DAG_OWNER='***' AIRFLOW_CTX_DAG_ID='ecommerce_pipeline' AIRFLOW_CTX_TASK_ID='generate_data' AIRFLOW_CTX_EXECUTION_DATE='2023-01-01T11:00:00+00:00' AIRFLOW_CTX_TRY_NUMBER='1' AIRFLOW_CTX_DAG_RUN_ID='scheduled__2023-01-01T11:00:00+00:00'
[2025-04-09T16:20:31.432+0000] {taskinstance.py:1935} ERROR - Task failed with exception
Traceback (most recent call last):
  File "/home/airflow/.local/lib/python3.8/site-packages/airflow/operators/python.py", line 192, in execute
    return_value = self.execute_callable()
  File "/home/airflow/.local/lib/python3.8/site-packages/airflow/operators/python.py", line 209, in execute_callable
    return self.python_callable(*self.op_args, **self.op_kwargs)
  File "/opt/airflow/dags/dags_1.py", line 25, in generate_data
    with open('/opt/airflow/data/Staging/orders.csv', 'w', newline='') as csvfile:
FileNotFoundError: [Errno 2] No such file or directory: '/opt/airflow/data/Staging/orders.csv'
[2025-04-09T16:20:31.501+0000] {taskinstance.py:1398} INFO - Marking task as UP_FOR_RETRY. dag_id=ecommerce_pipeline, task_id=generate_data, execution_date=20230101T110000, start_date=20250409T162030, end_date=20250409T162031
[2025-04-09T16:20:31.583+0000] {standard_task_runner.py:104} ERROR - Failed to execute job 42 for task generate_data ([Errno 2] No such file or directory: '/opt/airflow/data/Staging/orders.csv'; 192)
[2025-04-09T16:20:31.644+0000] {local_task_job_runner.py:228} INFO - Task exited with return code 1
[2025-04-09T16:20:31.765+0000] {taskinstance.py:2776} INFO - 0 downstream tasks scheduled from follow-on schedule check
