[2025-04-09T16:20:30.803+0000] {taskinstance.py:1157} INFO - Dependencies all met for dep_context=non-requeueable deps ti=<TaskInstance: ecommerce_pipeline.generate_data manual__2025-04-09T15:50:37.421852+00:00 [queued]>
[2025-04-09T16:20:30.833+0000] {taskinstance.py:1157} INFO - Dependencies all met for dep_context=requeueable deps ti=<TaskInstance: ecommerce_pipeline.generate_data manual__2025-04-09T15:50:37.421852+00:00 [queued]>
[2025-04-09T16:20:30.836+0000] {taskinstance.py:1359} INFO - Starting attempt 1 of 2
[2025-04-09T16:20:30.907+0000] {taskinstance.py:1380} INFO - Executing <Task(PythonOperator): generate_data> on 2025-04-09 15:50:37.421852+00:00
[2025-04-09T16:20:30.931+0000] {standard_task_runner.py:57} INFO - Started process 197 to run task
[2025-04-09T16:20:30.948+0000] {standard_task_runner.py:84} INFO - Running: ['***', 'tasks', 'run', 'ecommerce_pipeline', 'generate_data', 'manual__2025-04-09T15:50:37.421852+00:00', '--job-id', '51', '--raw', '--subdir', 'DAGS_FOLDER/dags_1.py', '--cfg-path', '/tmp/tmp0siqtmtt']
[2025-04-09T16:20:30.973+0000] {standard_task_runner.py:85} INFO - Job 51: Subtask generate_data
[2025-04-09T16:20:31.180+0000] {task_command.py:415} INFO - Running <TaskInstance: ecommerce_pipeline.generate_data manual__2025-04-09T15:50:37.421852+00:00 [running]> on host db3312bb44e3
[2025-04-09T16:20:31.412+0000] {taskinstance.py:1660} INFO - Exporting env vars: AIRFLOW_CTX_DAG_OWNER='***' AIRFLOW_CTX_DAG_ID='ecommerce_pipeline' AIRFLOW_CTX_TASK_ID='generate_data' AIRFLOW_CTX_EXECUTION_DATE='2025-04-09T15:50:37.421852+00:00' AIRFLOW_CTX_TRY_NUMBER='1' AIRFLOW_CTX_DAG_RUN_ID='manual__2025-04-09T15:50:37.421852+00:00'
[2025-04-09T16:20:31.429+0000] {taskinstance.py:1935} ERROR - Task failed with exception
Traceback (most recent call last):
  File "/home/airflow/.local/lib/python3.8/site-packages/airflow/operators/python.py", line 192, in execute
    return_value = self.execute_callable()
  File "/home/airflow/.local/lib/python3.8/site-packages/airflow/operators/python.py", line 209, in execute_callable
    return self.python_callable(*self.op_args, **self.op_kwargs)
  File "/opt/airflow/dags/dags_1.py", line 25, in generate_data
    with open('/opt/airflow/data/Staging/orders.csv', 'w', newline='') as csvfile:
FileNotFoundError: [Errno 2] No such file or directory: '/opt/airflow/data/Staging/orders.csv'
[2025-04-09T16:20:31.475+0000] {taskinstance.py:1398} INFO - Marking task as UP_FOR_RETRY. dag_id=ecommerce_pipeline, task_id=generate_data, execution_date=20250409T155037, start_date=20250409T162030, end_date=20250409T162031
[2025-04-09T16:20:31.546+0000] {standard_task_runner.py:104} ERROR - Failed to execute job 51 for task generate_data ([Errno 2] No such file or directory: '/opt/airflow/data/Staging/orders.csv'; 197)
[2025-04-09T16:20:31.590+0000] {local_task_job_runner.py:228} INFO - Task exited with return code 1
[2025-04-09T16:20:31.732+0000] {taskinstance.py:2776} INFO - 0 downstream tasks scheduled from follow-on schedule check
